<robot name = "robot">
    <link name="Link1">
        <inertial>
            <origin xyz="0 0 1" rpy="0 0 0"/>
            <mass value="1" />
            <inertia ixx="100" ixy="0" ixz="0" iyy="100" iyz="0" izz="100" />
        </inertial>
        <visual>
            <origin xyz="0 0 1" rpy="0 0 0"/>
            <geometry>
                <box size="0.9595251606306096 1.061350361371912 1.0839613320442556" />
            </geometry>
            <material name="Blue">
                <color rgba="0 0 1.0 1.0"/>
            </material>
        </visual>
        <collision>
            <origin xyz="0 0 1" rpy="0 0 0"/>
            <geometry>
                <box size="0.9595251606306096 1.061350361371912 1.0839613320442556" />
            </geometry>
        </collision>
    </link>
    <joint name="Link1_Link2" type="revolute">
       <parent link="Link1"/>
       <child  link="Link2"/>
       <origin rpy="0 0 0" xyz="0.4797625803153048 0 1" />
       <axis xyz="0 1 0"/>
       <limit effort="0.0" lower="-3.14159" upper="3.14159" velocity="0.0"/>
    </joint>
    <link name="Link2">
        <inertial>
            <origin xyz="0.4823603921723631 0 0" rpy="0 0 0"/>
            <mass value="1" />
            <inertia ixx="100" ixy="0" ixz="0" iyy="100" iyz="0" izz="100" />
        </inertial>
        <visual>
            <origin xyz="0.4823603921723631 0 0" rpy="0 0 0"/>
            <geometry>
                <box size="0.9647207843447262 0.3077258600972304 0.7841477772356458" />
            </geometry>
            <material name="Green">
                <color rgba="0 1.0 0 1.0"/>
            </material>
        </visual>
        <collision>
            <origin xyz="0.4823603921723631 0 0" rpy="0 0 0"/>
            <geometry>
                <box size="0.9647207843447262 0.3077258600972304 0.7841477772356458" />
            </geometry>
        </collision>
    </link>
    <joint name="Link2_Link3" type="revolute">
       <parent link="Link2"/>
       <child  link="Link3"/>
       <origin rpy="0 0 0" xyz="0.9647207843447262 0 0" />
       <axis xyz="0 1 0"/>
       <limit effort="0.0" lower="-3.14159" upper="3.14159" velocity="0.0"/>
    </joint>
    <link name="Link3">
        <inertial>
            <origin xyz="0.11755608303968669 0 0" rpy="0 0 0"/>
            <mass value="1" />
            <inertia ixx="100" ixy="0" ixz="0" iyy="100" iyz="0" izz="100" />
        </inertial>
        <visual>
            <origin xyz="0.11755608303968669 0 0" rpy="0 0 0"/>
            <geometry>
                <box size="0.23511216607937338 0.6517870820566625 0.9969199251607769" />
            </geometry>
            <material name="Green">
                <color rgba="0 1.0 0 1.0"/>
            </material>
        </visual>
        <collision>
            <origin xyz="0.11755608303968669 0 0" rpy="0 0 0"/>
            <geometry>
                <box size="0.23511216607937338 0.6517870820566625 0.9969199251607769" />
            </geometry>
        </collision>
    </link>
    <joint name="Link3_Link4" type="revolute">
       <parent link="Link3"/>
       <child  link="Link4"/>
       <origin rpy="0 0 0" xyz="0.23511216607937338 0 0" />
       <axis xyz="0 1 0"/>
       <limit effort="0.0" lower="-3.14159" upper="3.14159" velocity="0.0"/>
    </joint>
    <link name="Link4">
        <inertial>
            <origin xyz="0.08758934471331016 0 0" rpy="0 0 0"/>
            <mass value="1" />
            <inertia ixx="100" ixy="0" ixz="0" iyy="100" iyz="0" izz="100" />
        </inertial>
        <visual>
            <origin xyz="0.08758934471331016 0 0" rpy="0 0 0"/>
            <geometry>
                <box size="0.17517868942662032 1.0568055461718653 0.683653722901709" />
            </geometry>
            <material name="Green">
                <color rgba="0 1.0 0 1.0"/>
            </material>
        </visual>
        <collision>
            <origin xyz="0.08758934471331016 0 0" rpy="0 0 0"/>
            <geometry>
                <box size="0.17517868942662032 1.0568055461718653 0.683653722901709" />
            </geometry>
        </collision>
    </link>
    <joint name="Link4_Link5" type="revolute">
       <parent link="Link4"/>
       <child  link="Link5"/>
       <origin rpy="0 0 0" xyz="0.17517868942662032 0 0" />
       <axis xyz="0 1 0"/>
       <limit effort="0.0" lower="-3.14159" upper="3.14159" velocity="0.0"/>
    </joint>
    <link name="Link5">
        <inertial>
            <origin xyz="0.1616261691552146 0 0" rpy="0 0 0"/>
            <mass value="1" />
            <inertia ixx="100" ixy="0" ixz="0" iyy="100" iyz="0" izz="100" />
        </inertial>
        <visual>
            <origin xyz="0.1616261691552146 0 0" rpy="0 0 0"/>
            <geometry>
                <box size="0.3232523383104292 0.4801936977685681 0.20627140337105063" />
            </geometry>
            <material name="Green">
                <color rgba="0 1.0 0 1.0"/>
            </material>
        </visual>
        <collision>
            <origin xyz="0.1616261691552146 0 0" rpy="0 0 0"/>
            <geometry>
                <box size="0.3232523383104292 0.4801936977685681 0.20627140337105063" />
            </geometry>
        </collision>
    </link>
    <joint name="Link5_Link6" type="revolute">
       <parent link="Link5"/>
       <child  link="Link6"/>
       <origin rpy="0 0 0" xyz="0.3232523383104292 0 0" />
       <axis xyz="0 1 0"/>
       <limit effort="0.0" lower="-3.14159" upper="3.14159" velocity="0.0"/>
    </joint>
    <link name="Link6">
        <inertial>
            <origin xyz="0.5482162590385976 0 0" rpy="0 0 0"/>
            <mass value="1" />
            <inertia ixx="100" ixy="0" ixz="0" iyy="100" iyz="0" izz="100" />
        </inertial>
        <visual>
            <origin xyz="0.5482162590385976 0 0" rpy="0 0 0"/>
            <geometry>
                <box size="1.0964325180771952 0.8553717801163367 0.6507758442195755" />
            </geometry>
            <material name="Green">
                <color rgba="0 1.0 0 1.0"/>
            </material>
        </visual>
        <collision>
            <origin xyz="0.5482162590385976 0 0" rpy="0 0 0"/>
            <geometry>
                <box size="1.0964325180771952 0.8553717801163367 0.6507758442195755" />
            </geometry>
        </collision>
    </link>
    <joint name="Link6_Link7" type="revolute">
       <parent link="Link6"/>
       <child  link="Link7"/>
       <origin rpy="0 0 0" xyz="1.0964325180771952 0 0" />
       <axis xyz="0 1 0"/>
       <limit effort="0.0" lower="-3.14159" upper="3.14159" velocity="0.0"/>
    </joint>
    <link name="Link7">
        <inertial>
            <origin xyz="0.2954062376214762 0 0" rpy="0 0 0"/>
            <mass value="1" />
            <inertia ixx="100" ixy="0" ixz="0" iyy="100" iyz="0" izz="100" />
        </inertial>
        <visual>
            <origin xyz="0.2954062376214762 0 0" rpy="0 0 0"/>
            <geometry>
                <box size="0.5908124752429524 0.43239837564249445 0.35948189096797045" />
            </geometry>
            <material name="Green">
                <color rgba="0 1.0 0 1.0"/>
            </material>
        </visual>
        <collision>
            <origin xyz="0.2954062376214762 0 0" rpy="0 0 0"/>
            <geometry>
                <box size="0.5908124752429524 0.43239837564249445 0.35948189096797045" />
            </geometry>
        </collision>
    </link>
    <joint name="Link7_Link8" type="revolute">
       <parent link="Link7"/>
       <child  link="Link8"/>
       <origin rpy="0 0 0" xyz="0.5908124752429524 0 0" />
       <axis xyz="0 1 0"/>
       <limit effort="0.0" lower="-3.14159" upper="3.14159" velocity="0.0"/>
    </joint>
    <link name="Link8">
        <inertial>
            <origin xyz="0.39325920674820736 0 0" rpy="0 0 0"/>
            <mass value="1" />
            <inertia ixx="100" ixy="0" ixz="0" iyy="100" iyz="0" izz="100" />
        </inertial>
        <visual>
            <origin xyz="0.39325920674820736 0 0" rpy="0 0 0"/>
            <geometry>
                <box size="0.7865184134964147 1.2948417679318043 0.6446652611264142" />
            </geometry>
            <material name="Blue">
                <color rgba="0 0 1.0 1.0"/>
            </material>
        </visual>
        <collision>
            <origin xyz="0.39325920674820736 0 0" rpy="0 0 0"/>
            <geometry>
                <box size="0.7865184134964147 1.2948417679318043 0.6446652611264142" />
            </geometry>
        </collision>
    </link>
    <joint name="Link8_Link9" type="revolute">
       <parent link="Link8"/>
       <child  link="Link9"/>
       <origin rpy="0 0 0" xyz="0.7865184134964147 0 0" />
       <axis xyz="0 1 0"/>
       <limit effort="0.0" lower="-3.14159" upper="3.14159" velocity="0.0"/>
    </joint>
    <link name="Link9">
        <inertial>
            <origin xyz="0.13317437645702374 0 0" rpy="0 0 0"/>
            <mass value="1" />
            <inertia ixx="100" ixy="0" ixz="0" iyy="100" iyz="0" izz="100" />
        </inertial>
        <visual>
            <origin xyz="0.13317437645702374 0 0" rpy="0 0 0"/>
            <geometry>
                <box size="0.26634875291404747 0.37805320059117403 0.897420744343846" />
            </geometry>
            <material name="Blue">
                <color rgba="0 0 1.0 1.0"/>
            </material>
        </visual>
        <collision>
            <origin xyz="0.13317437645702374 0 0" rpy="0 0 0"/>
            <geometry>
                <box size="0.26634875291404747 0.37805320059117403 0.897420744343846" />
            </geometry>
        </collision>
    </link>
    <joint name="Link9_Link10" type="revolute">
       <parent link="Link9"/>
       <child  link="Link10"/>
       <origin rpy="0 0 0" xyz="0.26634875291404747 0 0" />
       <axis xyz="0 1 0"/>
       <limit effort="0.0" lower="-3.14159" upper="3.14159" velocity="0.0"/>
    </joint>
    <link name="Link10">
        <inertial>
            <origin xyz="0.20583838541400135 0 0" rpy="0 0 0"/>
            <mass value="1" />
            <inertia ixx="100" ixy="0" ixz="0" iyy="100" iyz="0" izz="100" />
        </inertial>
        <visual>
            <origin xyz="0.20583838541400135 0 0" rpy="0 0 0"/>
            <geometry>
                <box size="0.4116767708280027 0.4840915069330652 0.5146078305621253" />
            </geometry>
            <material name="Green">
                <color rgba="0 1.0 0 1.0"/>
            </material>
        </visual>
        <collision>
            <origin xyz="0.20583838541400135 0 0" rpy="0 0 0"/>
            <geometry>
                <box size="0.4116767708280027 0.4840915069330652 0.5146078305621253" />
            </geometry>
        </collision>
    </link>
    <joint name="Link10_Link11" type="revolute">
       <parent link="Link10"/>
       <child  link="Link11"/>
       <origin rpy="0 0 0" xyz="0.4116767708280027 0 0" />
       <axis xyz="0 1 0"/>
       <limit effort="0.0" lower="-3.14159" upper="3.14159" velocity="0.0"/>
    </joint>
    <link name="Link11">
        <inertial>
            <origin xyz="0.22708672669253088 0 0" rpy="0 0 0"/>
            <mass value="1" />
            <inertia ixx="100" ixy="0" ixz="0" iyy="100" iyz="0" izz="100" />
        </inertial>
        <visual>
            <origin xyz="0.22708672669253088 0 0" rpy="0 0 0"/>
            <geometry>
                <box size="0.45417345338506176 1.110995171033885 0.5591242123943702" />
            </geometry>
            <material name="Green">
                <color rgba="0 1.0 0 1.0"/>
            </material>
        </visual>
        <collision>
            <origin xyz="0.22708672669253088 0 0" rpy="0 0 0"/>
            <geometry>
                <box size="0.45417345338506176 1.110995171033885 0.5591242123943702" />
            </geometry>
        </collision>
    </link>
</robot>