<sdf>
    <joint name="Torso_FrontLeg" type="revolute">
       <parent link="Torso"/>
       <child  link="FrontLeg"/>
       <origin rpy="0 0 0" xyz="0 0.5 1" />
     <axis xyz="1 0 0"/>
       <limit effort="0.0" lower="-3.14159" upper="3.14159" velocity="0.0"/>
    </joint>
    <model name="FrontLeg">
        <pose>0 0.5 0 0 0 0 </pose>
        <link name="FrontLeg">
            <inertial>
                <mass>1.0</mass>
                <inertia>
                    <ixx>0.083</ixx>
                    <ixy>0.0</ixy>
                    <ixz>0.0</ixz>
                    <iyy>0.083</iyy>
                    <iyz>0.0</iyz>
                    <izz>0.083</izz>
                </inertia>
            </inertial>
            <collision>
                <geometry>
                   <box>
                      <size>0.2 1 0.2</size>
                   </box>
                </geometry>
            </collision>
            <visual>
                <geometry>
                   <box>
                      <size>0.2 1 0.2</size>
                   </box>
                </geometry>
            </visual>
        </link>
    </model>
    <joint name="Torso_BackLeg" type="revolute">
       <parent link="Torso"/>
       <child  link="BackLeg"/>
       <origin rpy="0 0 0" xyz="0 -0.5 1" />
     <axis xyz="1 0 0"/>
       <limit effort="0.0" lower="-3.14159" upper="3.14159" velocity="0.0"/>
    </joint>
    <model name="BackLeg">
        <pose>0 -0.5 0 0 0 0 </pose>
        <link name="BackLeg">
            <inertial>
                <mass>1.0</mass>
                <inertia>
                    <ixx>0.083</ixx>
                    <ixy>0.0</ixy>
                    <ixz>0.0</ixz>
                    <iyy>0.083</iyy>
                    <iyz>0.0</iyz>
                    <izz>0.083</izz>
                </inertia>
            </inertial>
            <collision>
                <geometry>
                   <box>
                      <size>0.2 1 0.2</size>
                   </box>
                </geometry>
            </collision>
            <visual>
                <geometry>
                   <box>
                      <size>0.2 1 0.2</size>
                   </box>
                </geometry>
            </visual>
        </link>
    </model>
    <joint name="Torso_LeftLeg" type="revolute">
       <parent link="Torso"/>
       <child  link="LeftLeg"/>
       <origin rpy="0 0 0" xyz="-0.5 0 1" />
     <axis xyz="0 1 0"/>
       <limit effort="0.0" lower="-3.14159" upper="3.14159" velocity="0.0"/>
    </joint>
    <model name="LeftLeg">
        <pose>-0.5 0 0 0 0 0 </pose>
        <link name="LeftLeg">
            <inertial>
                <mass>1.0</mass>
                <inertia>
                    <ixx>0.083</ixx>
                    <ixy>0.0</ixy>
                    <ixz>0.0</ixz>
                    <iyy>0.083</iyy>
                    <iyz>0.0</iyz>
                    <izz>0.083</izz>
                </inertia>
            </inertial>
            <collision>
                <geometry>
                   <box>
                      <size>1 0.2 0.2</size>
                   </box>
                </geometry>
            </collision>
            <visual>
                <geometry>
                   <box>
                      <size>1 0.2 0.2</size>
                   </box>
                </geometry>
            </visual>
        </link>
    </model>
    <joint name="Torso_RightLeg" type="revolute">
       <parent link="Torso"/>
       <child  link="RightLeg"/>
       <origin rpy="0 0 0" xyz="0.5 0 1" />
     <axis xyz="0 1 0"/>
       <limit effort="0.0" lower="-3.14159" upper="3.14159" velocity="0.0"/>
    </joint>
    <model name="RightLeg">
        <pose>0.5 0 0 0 0 0 </pose>
        <link name="RightLeg">
            <inertial>
                <mass>1.0</mass>
                <inertia>
                    <ixx>0.083</ixx>
                    <ixy>0.0</ixy>
                    <ixz>0.0</ixz>
                    <iyy>0.083</iyy>
                    <iyz>0.0</iyz>
                    <izz>0.083</izz>
                </inertia>
            </inertial>
            <collision>
                <geometry>
                   <box>
                      <size>1 0.2 0.2</size>
                   </box>
                </geometry>
            </collision>
            <visual>
                <geometry>
                   <box>
                      <size>1 0.2 0.2</size>
                   </box>
                </geometry>
            </visual>
        </link>
    </model>
    <joint name="FrontLeg_FrontLowerLeg" type="revolute">
       <parent link="FrontLeg"/>
       <child  link="FrontLowerLeg"/>
       <origin rpy="0 0 0" xyz="0 1 0" />
     <axis xyz="1 0 0"/>
       <limit effort="0.0" lower="-3.14159" upper="3.14159" velocity="0.0"/>
    </joint>
    <model name="FrontLowerLeg">
        <pose>0 0 -0.5 0 0 0 </pose>
        <link name="FrontLowerLeg">
            <inertial>
                <mass>1.0</mass>
                <inertia>
                    <ixx>0.083</ixx>
                    <ixy>0.0</ixy>
                    <ixz>0.0</ixz>
                    <iyy>0.083</iyy>
                    <iyz>0.0</iyz>
                    <izz>0.083</izz>
                </inertia>
            </inertial>
            <collision>
                <geometry>
                   <box>
                      <size>0.2 0.2 1</size>
                   </box>
                </geometry>
            </collision>
            <visual>
                <geometry>
                   <box>
                      <size>0.2 0.2 1</size>
                   </box>
                </geometry>
            </visual>
        </link>
    </model>
    <joint name="BackLeg_BackLowerLeg" type="revolute">
       <parent link="BackLeg"/>
       <child  link="BackLowerLeg"/>
       <origin rpy="0 0 0" xyz="0 -1 0" />
     <axis xyz="1 0 0"/>
       <limit effort="0.0" lower="-3.14159" upper="3.14159" velocity="0.0"/>
    </joint>
    <model name="BackLowerLeg">
        <pose>0 0 -0.5 0 0 0 </pose>
        <link name="BackLowerLeg">
            <inertial>
                <mass>1.0</mass>
                <inertia>
                    <ixx>0.083</ixx>
                    <ixy>0.0</ixy>
                    <ixz>0.0</ixz>
                    <iyy>0.083</iyy>
                    <iyz>0.0</iyz>
                    <izz>0.083</izz>
                </inertia>
            </inertial>
            <collision>
                <geometry>
                   <box>
                      <size>0.2 0.2 1</size>
                   </box>
                </geometry>
            </collision>
            <visual>
                <geometry>
                   <box>
                      <size>0.2 0.2 1</size>
                   </box>
                </geometry>
            </visual>
        </link>
    </model>
    <joint name="LeftLeg_LeftLowerLeg" type="revolute">
       <parent link="LeftLeg"/>
       <child  link="LeftLowerLeg"/>
       <origin rpy="0 0 0" xyz="-1 0 0" />
     <axis xyz="0 1 0"/>
       <limit effort="0.0" lower="-3.14159" upper="3.14159" velocity="0.0"/>
    </joint>
    <model name="LeftLowerLeg">
        <pose>0 0 -0.5 0 0 0 </pose>
        <link name="LeftLowerLeg">
            <inertial>
                <mass>1.0</mass>
                <inertia>
                    <ixx>0.083</ixx>
                    <ixy>0.0</ixy>
                    <ixz>0.0</ixz>
                    <iyy>0.083</iyy>
                    <iyz>0.0</iyz>
                    <izz>0.083</izz>
                </inertia>
            </inertial>
            <collision>
                <geometry>
                   <box>
                      <size>0.2 0.2 1</size>
                   </box>
                </geometry>
            </collision>
            <visual>
                <geometry>
                   <box>
                      <size>0.2 0.2 1</size>
                   </box>
                </geometry>
            </visual>
        </link>
    </model>
    <joint name="RightLeg_RightLowerLeg" type="revolute">
       <parent link="RightLeg"/>
       <child  link="RightLowerLeg"/>
       <origin rpy="0 0 0" xyz="1 0 0" />
     <axis xyz="0 1 0"/>
       <limit effort="0.0" lower="-3.14159" upper="3.14159" velocity="0.0"/>
    </joint>
    <model name="RightLowerLeg">
        <pose>0 0 -0.5 0 0 0 </pose>
        <link name="RightLowerLeg">
            <inertial>
                <mass>1.0</mass>
                <inertia>
                    <ixx>0.083</ixx>
                    <ixy>0.0</ixy>
                    <ixz>0.0</ixz>
                    <iyy>0.083</iyy>
                    <iyz>0.0</iyz>
                    <izz>0.083</izz>
                </inertia>
            </inertial>
            <collision>
                <geometry>
                   <box>
                      <size>0.2 0.2 1</size>
                   </box>
                </geometry>
            </collision>
            <visual>
                <geometry>
                   <box>
                      <size>0.2 0.2 1</size>
                   </box>
                </geometry>
            </visual>
        </link>
    </model>
</sdf>